[
  {
    "id" : "3fdb61b1-3bfe-4c61-9844-2b2e4dde3e9b",
    "prId" : 2282,
    "comments" : [
      {
        "id" : "8a63688e-936a-4cfe-b955-f1b914a93d1d",
        "parentId" : null,
        "author" : {
          "login" : "gerolf-da",
          "name" : "Gerolf Seitz",
          "avatarUrl" : "https://avatars1.githubusercontent.com/u/29121423?u=f683aa614e742c653ae8c01b194905dcdef6e974&v=4"
        },
        "body" : "Why does this throw the exception outside of the `Future`? To not have to \"wire\" the call to `skip` into a for-comprehension?",
        "createdAt" : "2019-08-06T12:31:37Z",
        "updatedAt" : "2019-08-09T14:28:54Z",
        "lastEditedBy" : {
          "login" : "gerolf-da",
          "name" : "Gerolf Seitz",
          "avatarUrl" : "https://avatars1.githubusercontent.com/u/29121423?u=f683aa614e742c653ae8c01b194905dcdef6e974&v=4"
        },
        "tags" : [
          {
            "value" : "outdated"
          }
        ]
      },
      {
        "id" : "8299412e-6354-4fc9-b346-7c8c1259cd9e",
        "parentId" : "8a63688e-936a-4cfe-b955-f1b914a93d1d",
        "author" : {
          "login" : "stefanobaghino-da",
          "name" : "Stefano Baghino",
          "avatarUrl" : "https://avatars2.githubusercontent.com/u/43749967?v=4"
        },
        "body" : "I realized that I was originally actually starting tests from the main thread, which could break the seal around exceptions thrown in the test body (hence all the _PLEASE REPORT THIS_ error messages to cover uncaught exceptions). So I moved to this other approach. I just noticed that now the return type is completely wrong. I could keep this as it was, the most important thing for me was not letting any exception escape the test runner and a call to `skip` made me notice it.",
        "createdAt" : "2019-08-06T16:39:02Z",
        "updatedAt" : "2019-08-09T14:28:54Z",
        "lastEditedBy" : {
          "login" : "stefanobaghino-da",
          "name" : "Stefano Baghino",
          "avatarUrl" : "https://avatars2.githubusercontent.com/u/43749967?v=4"
        },
        "tags" : [
          {
            "value" : "outdated"
          }
        ]
      },
      {
        "id" : "14aa8843-8ca0-423a-ac18-94e053e43e34",
        "parentId" : "8a63688e-936a-4cfe-b955-f1b914a93d1d",
        "author" : {
          "login" : "stefanobaghino-da",
          "name" : "Stefano Baghino",
          "avatarUrl" : "https://avatars2.githubusercontent.com/u/43749967?v=4"
        },
        "body" : "Addressed by https://github.com/digital-asset/daml/pull/2282/commits/e41532036369394d18a9a5278323f476d24fce77",
        "createdAt" : "2019-08-06T16:40:49Z",
        "updatedAt" : "2019-08-09T14:28:54Z",
        "lastEditedBy" : {
          "login" : "stefanobaghino-da",
          "name" : "Stefano Baghino",
          "avatarUrl" : "https://avatars2.githubusercontent.com/u/43749967?v=4"
        },
        "tags" : [
          {
            "value" : "outdated"
          }
        ]
      }
    ],
    "commit" : "c0ec2e9d435c3c835828ec8bb046a8d6fe9c4a32",
    "line" : null,
    "diffHunk" : "@@ -24,7 +24,7 @@ private[testtool] abstract class LedgerTestSuite(val session: LedgerSession) {\n \n   val tests: Vector[LedgerTest] = Vector.empty\n \n-  final def skip(reason: String): Future[Unit] = Future.failed(new SkipTestException(reason))\n+  final def skip(reason: String): Future[Unit] = throw new SkipTestException(reason)"
  }
]